Workbook

Sheet BAU
A1: AQUECIMENTO
A2: Considerado:
A3: Radiador eléctrico, 1.5 kW, COP = 1
A5: ARREFECIMENTO
A6: Considerado:
A7: AC, 2.6 kW térmicos, COP = 2.6, caudal ar = 320 m3/h
A10: MODELAÇÃO DESIGNBUILDER:
A11: Aquecimento: 1 radiador eléctrico p/zona
A12: Arrefecimento: 1 packaged terminal air conditioner por zona apenas em arrefecimento

Sheet Multisplit
A1: NECESSIDADES TÉRMICAS (heating/cooling design)
B2: Heating (kW) | C2: Cooling (kW)
A5: A preencher (idêntico ao considerado anteriormente)
A8: MODELAÇÃO DESIGNBUILDER:
A9: Aquecimento/Arrefecimento: 1 packaged terminal heat pump por zona (com as especificações das unidades interiores do multisplit e os COP da unidade exterior)

Sheet HP
A1: NECESSIDADES TÉRMICAS (heating/cooling design)
B2: Heating (kW) | C2: Cooling (kW)
A5: A preencher (idêntico ao considerado anteriormente)
A8: MODELAÇÃO DESIGNBUILDER:
A9: Aquecimento: 1 bomba de calor ar-água (heating) que alimenta as serpentinas dos fancoils (1 por zona)
A10: Arrefecimento: 1 bomba de calor ar-água (cooling) que alimenta as serpentinas dos fancoils (1 por zona)

Sheet PV
B1: C (m) | C1: L (m) | D1: A (m2) | E1: P (W) | F1: P' (W/m2) | G1: P_12 m2 (W) | H1: n_módulos | I1: Eficiência (%) | J1: Link
A2: A | B2: 1.762 | C2: 1.134 | D2: =B2*C2 -> 1.998108 | E2: 455 | F2: =E2/D2 -> 227.71542 | G2: =F2*12 -> 2732.585 | H2: =12/D2 -> 6.0056814 | I2: 22.8 | J2: https://www.solarshop.pt/pt/hyundai-hyundai-455w-hit-h455le-fb-painel-solar-unidade
A3: B | B3: 1.762 | C3: 1.134 | D3: =B3*C3 -> 1.998108 | E3: 450 | F3: =E3/D3 -> 225.21305 | G3: =F3*12 -> 2702.5566 | H3: =12/D3 -> 6.0056814 | I3: 22.5 | J3: https://www.solarshop.pt/pt/dmegc-dmegc-450w---dm450g12rt-painel-solar-unidade
G4: =AVERAGE(G2:G3) -> 2717.5708 | H4: =AVERAGE(H2:H3) -> 6.0056814 | I4: =AVERAGE(I2:I3) -> 22.65
A5: Para 12 m2 tem-se:
A6: 6 módulos
A7: ~2700 W total
A8: Considera-se um performance ratio de 75% para se obter <1500 kWh/kWp/ano (típico de Coimbra): eficiência PV = 22.7*0.75 = ~17% (constante no programa; i.e., média que considera as variações diárias e sazonais)
A9: Considera-se uma inclinação de 30% (igual à inclinação do telhado)
A10: Orientação Sudoeste
A12: Inversor 97%
A13: Bateria 5 kWh, 95% effic

Sheet EPW
A1: Present day
A2: PRT_CN_Coimbra.AP.085480_TMYx.2007-2021
A3: https://climate.onebuilding.org/WMO_Region_6_Europe/PRT_Portugal/index.html
A4: Jan | B4: Feb | C4: Mar | D4: Apr | E4: May | F4: Jun | G4: Jul | H4: Aug | I4: Sep | J4: Oct | K4: Nov | L4: Dec
A5: 9.3 | B5: 10.2 | C5: 11.9 | D5: 14.4 | E5: 16 | F5: 18.4 | G5: 20.1 | H5: 20.9 | I5: 19.7 | J5: 17.2 | K5: 12.5 | L5: 11.1
A7: 2050 SSP2-4.5
A8: Morphed projections of PRT_CN_Coimbra.AP.085480_TMYx.2007-2021, using the Future Weather Generator v. 4.3.0 (ensemble of all CMIP6 models)
A9: https://future-weather-generator.adai.pt/
A10: Jan | B10: Feb | C10: Mar | D10: Apr | E10: May | F10: Jun | G10: Jul | H10: Aug | I10: Sep | J10: Oct | K10: Nov | L10: Dec
A11: 10.3 | B11: 11.2 | C11: 13 | D11: 15.7 | E11: 17.5 | F11: 20.2 | G11: 22.1 | H11: 22.8 | I11: 21.5 | J11: 18.9 | K11: 13.7 | L11: 12.1
A13: 2050 SSP3-7.0
A14: Morphed projections of PRT_CN_Coimbra.AP.085480_TMYx.2007-2021, using the Future Weather Generator v. 4.3.0 (ensemble of all CMIP6 models)
A15: https://future-weather-generator.adai.pt/
A16: Jan | B16: Feb | C16: Mar | D16: Apr | E16: May | F16: Jun | G16: Jul | H16: Aug | I16: Sep | J16: Oct | K16: Nov | L16: Dec
A17: 10.5 | B17: 11.4 | C17: 13 | D17: 15.8 | E17: 17.9 | F17: 20.5 | G17: 22.4 | H17: 23 | I17: 21.7 | J17: 19.1 | K17: 13.9 | L17: 12.5
A19: 2080 SSP3-7.0
A20: Morphed projections of PRT_CN_Coimbra.AP.085480_TMYx.2007-2021, using the Future Weather Generator v. 4.3.0 (ensemble of all CMIP6 models)
A21: https://future-weather-generator.adai.pt/
A22: Jan | B22: Feb | C22: Mar | D22: Apr | E22: May | F22: Jun | G22: Jul | H22: Aug | I22: Sep | J22: Oct | K22: Nov | L22: Dec
A23: 11.4 | B23: 12.3 | C23: 14 | D23: 17 | E23: 19.3 | F23: 22.2 | G23: 23.8 | H23: 24.4 | I23: 23.4 | J23: 20.5 | K23: 15.1 | L23: 13.4

Sheet BAU Results
B1: Building useful area (m2) | C1: 437.54
B2: Conditioned useful area (m2) | C2: 237.53
A4: PRESENT DAY
A6: BAU | G6: BAU
A7: Annual | G7: Monthly
A8: GEN. | B8: Equipment electricity (kWh) | C8: 6336.6 | H8: Lighting elect. (kWh) | I8: Equipment elect. (kWh) | J8: Fans elect. (kWh) | K8: Pumps elect. (kWh) | L8: Heating elect. (kWh) | M8: Cooling elect. (kWh)
B9: Lighting electricity (kWh) | C9: 866.71 | D9: Per building m2 | E9: Per conditioned m2 | G9: January | H9: 79.87 | I9: 587.12 | J9: 10.89 | K9: 0 | L9: 847.21 | M9: 0
A10: HVAC | B10: Heating thermal needs (kWh) | C10: 2896.84 | G10: February | H10: 73.11 | I10: 534.64 | J10: 9.21 | K10: 0 | L10: 636.08 | M10: 0
B11: Heating electricity (kWh) | C11: 3061.52 | D11: =C11/$C$1 -> 6.9971203 | E11: =C11/$C$2 -> 12.888982 | G11: March | H11: 85.5 | I11: 617.92 | J11: 7.97 | K11: 0 | L11: 398.39 | M11: 0
B12: Heating Setpoint Unmet Degree-Hours [°C·hr] - TOTAL | C12: 1894.65 | G12: April | H12: 73.11 | I12: 534.64 | J12: 5.27 | K12: 0 | L12: 204.47 | M12: 5.78
G13: May | H13: 83.76 | I13: 613.72 | J13: 1.98 | K13: 0 | L13: 41.51 | M13: 19.83
G14: June | H14: 79.87 | I14: 587.12 | J14: 0.63 | K14: 0 | L14: 3.07 | M14: 48.36
B15: Cooling thermal needs (kWh) | C15: 957.27 | G15: July | H15: 76.49 | I15: 560.88 | J15: 1.49 | K15: 0 | L15: 0.1 | M15: 139.2
B16: Cooling electricity (kWh) | C16: 367.58 | D16: =C16/$C$1 -> 0.84010605 | E16: =C16/$C$2 -> 1.5475098 | G16: August | H16: 0 | I16: 0 | J16: 0 | K16: 0 | L16: 0 | M16: 0
B17: Cooling Setpoint Unmet Degree-Hours [°C·hr] - TOTAL | C17: 18.78 | G17: September | H17: 78.23 | I17: 565.08 | J17: 1.43 | K17: 0 | L17: 0.38 | M17: 132.58
G18: October | H18: 79.87 | I18: 587.12 | J18: 1.03 | K18: 0 | L18: 15.27 | M18: 21.13
G19: November | H19: 80.39 | I19: 587.48 | J19: 7.05 | K19: 0 | L19: 354.16 | M19: 0.69
B20: Fans (kWh) | C20: 56.24 | G20: December | H20: 76.49 | I20: 560.88 | J20: 9.3 | K20: 0 | L20: 560.86 | M20: 0
A21: DHW | B21: Pumps (kWh)
B22: DHW thermal needs (kWh) | G22: Annual Sum | H22: 866.71 | I22: 6336.6 | J22: 56.24 | K22: 0 | L22: 3061.52 | M22: 367.58
B23: DHW nat. gas (kWh)
B24: -
B25: TOTAL ELECTRICITY (kWh) | C25: =C8+C9+C11+C16+C20+C21 -> 10688.65
A27: PV | B27: PV generation (kWh) | C27: 3748.942
B28: Net Storage (kWh) | C28: -35.37
B29: Inverter losses (kWh) | C29: -111.41
B30: Useful PV generation (kWh) | C30: =C27+C28+C29 -> 3602.162
B31: Surplus to utility (kWh) | C31: -1137.993
B32: Generation to building (kWh) | C32: =C30+C31 -> 2464.169
B33: Electricity from utility (kWh) | C33: 8224.472
B34: Building needs (kWh) | C34: =C32+C33 -> 10688.641
A40: 2050 SSP2-4.5
A42: BAU | G42: BAU
A43: Annual | G43: Monthly
A44: GEN. | B44: Equipment electricity (kWh) | C44: 6336.6 | H44: Lighting elect. (kWh) | I44: Equipment elect. (kWh) | J44: Fans elect. (kWh) | K44: Pumps elect. (kWh) | L44: Heating elect. (kWh) | M44: Cooling elect. (kWh)
B45: Lighting electricity (kWh) | C45: 866.71 | D45: Per building m2 | E45: Per conditioned m2 | G45: January | H45: 79.87 | I45: 587.12 | J45: 9.92 | K45: 0 | L45: 628.51 | M45: 0
A46: HVAC | B46: Heating thermal needs (kWh) | C46: 1890.76 | G46: February | H46: 73.11 | I46: 534.64 | J46: 8.2 | K46: 0 | L46: 463.11 | M46: 0
B47: Heating electricity (kWh) | C47: 2022.96 | D47: =C47/$C$1 -> 4.6234859 | E47: =C47/$C$2 -> 8.5166505 | G47: March | H47: 85.5 | I47: 617.92 | J47: 6.07 | K47: 0 | L47: 233.14 | M47: 1.01
B48: Heating Setpoint Unmet Degree-Hours [°C·hr] - TOTAL | C48: 1201.66 | G48: April | H48: 73.11 | I48: 534.64 | J48: 3.42 | K48: 0 | L48: 97.08 | M48: 19.92
G49: May | H49: 83.76 | I49: 613.72 | J49: 1.18 | K49: 0 | L49: 8.92 | M49: 60.88
...

Sheet Multisplit Results
B1: Building useful area (m2) | C1: ='BAU Results'!C1 -> 437.54
B2: Conditioned useful area (m2) | C2: ='BAU Results'!C2 -> 237.53
A4: PRESENT DAY
A6: Multisplit | G6: Multisplit
A7: Annual | G7: Monthly
A8: GEN. | B8: Equipment electricity (kWh) | C8: 6336.6 | H8: Lighting elect. (kWh) | I8: Equipment elect. (kWh) | J8: Fans elect. (kWh) | K8: Pumps elect. (kWh) | L8: Heating elect. (kWh) | M8: Cooling elect. (kWh)
B9: Lighting electricity (kWh) | C9: 866.71 | D9: Per building m2 | E9: Per conditioned m2 | G9: January | H9: 79.87 | I9: 587.12 | J9: 3.96 | K9: 0 | L9: 180.17 | M9: 0
A10: HVAC | B10: Heating thermal needs (kWh) | C10: ='BAU Results'!C10 -> 2896.84 | G10: February | H10: 73.11 | I10: 534.64 | J10: 2.93 | K10: 0 | L10: 135.79 | M10: 0
B11: Heating electricity (kWh) | C11: 642.54 | D11: =C11/$C$1 -> 1.4685286 | E11: =C11/$C$2 -> 2.7050899 | G11: March | H11: 85.5 | I11: 617.92 | J11: 1.8 | K11: 0 | L11: 83.25 | M11: 0
B12: Heating Setpoint Unmet Degree-Hours [°C·hr] - TOTAL | C12: 180.54 | G12: April | H12: 73.11 | I12: 534.64 | J12: 0.97 | K12: 0 | L12: 41.4 | M12: 3.53
G13: May | H13: 83.76 | I13: 613.72 | J13: 0.43 | K13: 0 | L13: 8.23 | M13: 11.98
G14: June | H14: 79.87 | I14: 587.12 | J14: 0.62 | K14: 0 | L14: 0.6 | M14: 29.58
B15: Cooling thermal needs (kWh) | C15: ='BAU Results'!C15 -> 957.27 | G15: July | H15: 76.49 | I15: 560.88 | J15: 1.92 | K15: 0 | L15: 0.02 | M15: 85.07
B16: Cooling electricity (kWh) | C16: 224.55 | D16: =C16/$C$1 -> 0.51321022 | E16: =C16/$C$2 -> 0.94535427 | G16: August | H16: 0 | I16: 0 | J16: 0 | K16: 0 | L16: 0 | M16: 0
B17: Cooling Setpoint Unmet Degree-Hours [°C·hr] - TOTAL | C17: 3.96 | G17: September | H17: 78.23 | I17: 565.08 | J17: 1.77 | K17: 0 | L17: 0.07 | M17: 80.94
G18: October | H18: 79.87 | I18: 587.12 | J18: 0.31 | K18: 0 | L18: 3.07 | M18: 13.08
G19: November | H19: 80.39 | I19: 587.48 | J19: 1.6 | K19: 0 | L19: 73.54 | M19: 0.38
B20: Fans (kWh) | C20: 18.82 | G20: December | H20: 76.49 | I20: 560.88 | J20: 2.51 | K20: 0 | L20: 116.39 | M20: 0
A21: DHW | B21: Pumps (kWh)
B22: DHW thermal needs (kWh) | G22: Annual Sum | H22: 866.71 | I22: 6336.6 | J22: 18.82 | K22: 0 | L22: 642.54 | M22: 224.55
B23: DHW electricity HP (kWh)
B24: DHW electricity backup (kWh)
B25: TOTAL ELECTRICITY (kWh) | C25: =C8+C9+C11+C16+C20+C21+C23+C24 -> 8089.22
A27: PV | B27: PV generation (kWh) | C27: 3748.942
B28: Net Storage (kWh) | C28: -35.37
B29: Inverter losses (kWh) | C29: -111.41
B30: Useful PV generation (kWh) | C30: =C27+C28+C29 -> 3602.162
B31: Surplus to utility (kWh) | C31: -1137.993
B32: Generation to building (kWh) | C32: =C30+C31 -> 2464.169
B33: Electricity from utility (kWh) | C33: 5625.052
B34: Building needs (kWh) | C34: =C32+C33 -> 8089.221
A39: 2050 SSP2-4.5
A41: Multisplit | G41: Multisplit
A42: Annual | G42: Monthly
A43: GEN. | B43: Equipment electricity (kWh) | C43: 6336.6 | H43: Lighting elect. (kWh) | I43: Equipment elect. (kWh) | J43: Fans elect. (kWh) | K43: Pumps elect. (kWh) | L43: Heating elect. (kWh) | M43: Cooling elect. (kWh)
B44: Lighting electricity (kWh) | C44: 866.71 | D44: Per building m2 | E44: Per conditioned m2 | G44: January | H44: 79.87 | I44: 587.12 | J44: 2.89 | K44: 0 | L44: 131.11 | M44: 0
A45: HVAC | B45: Heating thermal needs (kWh) | C45: ='BAU Results'!C46 -> 1890.76 | G45: February | H45: 73.11 | I45: 534.64 | J45: 2.09 | K45: 0 | L45: 97.32 | M45: 0
B46: Heating electricity (kWh) | C46: 417.95 | D46: =C46/$C$1 -> 0.95522695 | E46: =C46/$C$2 -> 1.7595672 | G46: March | H46: 85.5 | I46: 617.92 | J46: 1.05 | K46: 0 | L46: 47.88 | M46: 0.66
B47: Heating Setpoint Unmet Degree-Hours [°C·hr] - TOTAL | C47: 108.59 | G47: April | H47: 73.11 | I47: 534.64 | J47: 0.65 | K47: 0 | L47: 19.37 | M47: 12.54
G48: May | H48: 83.76 | I48: 613.72 | J48: 0.85 | K48: 0 | L48: 1.76 | M48: 37.14
...

Sheet HP Results
B1: Building useful area (m2) | C1: ='BAU Results'!C1 -> 437.54
B2: Conditioned useful area (m2) | C2: ='BAU Results'!C2 -> 237.53
A4: PRESENT DAY
A6: HP | G6: HP
A7: Annual | G7: Monthly
A8: GEN. | B8: Equipment electricity (kWh) | C8: 6336.6 | H8: Lighting elect. (kWh) | I8: Equipment elect. (kWh) | J8: Fans elect. (kWh) | K8: Pumps elect. (kWh) | L8: Heating elect. (kWh) | M8: Cooling elect. (kWh)
B9: Lighting electricity (kWh) | C9: 866.71 | D9: Per building m2 | E9: Per conditioned m2 | G9: January | H9: 79.87 | I9: 587.12 | J9: 3.51 | K9: 20.86 | L9: 246.73 | M9: 0
A10: HVAC | B10: Heating thermal needs (kWh) | C10: ='BAU Results'!C10 -> 2896.84 | G10: February | H10: 73.11 | I10: 534.64 | J10: 2.68 | K10: 16.48 | L10: 184.81 | M10: 0
B11: Heating electricity (kWh) | C11: 870.01 | D11: =C11/$C$1 -> 1.9884125 | E11: =C11/$C$2 -> 3.6627373 | G11: March | H11: 85.5 | I11: 617.92 | J11: 1.73 | K11: 11.15 | L11: 110.56 | M11: 0
B12: Heating Setpoint Unmet Degree-Hours [°C·hr] - TOTAL | C12: 82.65 | G12: April | H12: 73.11 | I12: 534.64 | J12: 1 | K12: 6.54 | L12: 55 | M12: 0.56
G13: May | H13: 83.76 | I13: 613.72 | J13: 0.52 | K13: 3.38 | L13: 11.21 | M13: 2.03
G14: June | H14: 79.87 | I14: 587.12 | J14: 0.64 | K14: 4.17 | L14: 0.89 | M14: 6.48
B15: Cooling thermal needs (kWh) | C15: ='BAU Results'!C15 -> 957.27 | G15: July | H15: 76.49 | I15: 560.88 | J15: 1.92 | K15: 11.39 | L15: 0.03 | M15: 27.68
B16: Cooling electricity (kWh) | C16: 60.85 | D16: =C16/$C$1 -> 0.139073 | E16: =C16/$C$2 -> 0.25617817 | G16: August | H16: 0 | I16: 0 | J16: 0 | K16: 0 | L16: 0 | M16: 0
B17: Cooling Setpoint Unmet Degree-Hours [°C·hr] - TOTAL | C17: 1.1 | G17: September | H17: 78.23 | I17: 565.08 | J17: 1.82 | K17: 10.83 | L17: 0.12 | M17: 21.67
G18: October | H18: 79.87 | I18: 587.12 | J18: 0.39 | K18: 2.42 | L18: 4.39 | M18: 2.37
G19: November | H19: 80.39 | I19: 587.48 | J19: 1.54 | K19: 9.93 | L19: 98.13 | M19: 0.05
B20: Fans (kWh) | C20: 18.1 | G20: December | H20: 76.49 | I20: 560.88 | J20: 2.36 | K20: 15.08 | L20: 158.14 | M20: 0
A21: DHW | B21: Pumps (kWh) | C21: 112.23
B22: DHW thermal needs (kWh) | G22: Annual Sum | H22: 866.71 | I22: 6336.6 | J22: 18.1 | K22: 112.23 | L22: 870.01 | M22: 60.85
B23: DHW electricity HP (kWh)
B24: DHW electricity backup (kWh)
B25: TOTAL ELECTRICITY (kWh) | C25: =C8+C9+C11+C16+C20+C21+C23+C24 -> 8264.5
A27: PV | B27: PV generation (kWh) | C27: 3748.942
B28: Net Storage (kWh) | C28: -35.37
B29: Inverter losses (kWh) | C29: -111.41
B30: Useful PV generation (kWh) | C30: =C27+C28+C29 -> 3602.162
B31: Surplus to utility (kWh) | C31: -1137.998
B32: Generation to building (kWh) | C32: =C30+C31 -> 2464.164
B33: Electricity from utility (kWh) | C33: 5800.337
B34: Building needs (kWh) | C34: =C32+C33 -> 8264.501
A38: 2050 SSP2-4.5
A40: HP | G40: HP
A41: Annual | G41: Monthly
A42: GEN. | B42: Equipment electricity (kWh) | C42: 6336.6 | H42: Lighting elect. (kWh) | I42: Equipment elect. (kWh) | J42: Fans elect. (kWh) | K42: Pumps elect. (kWh) | L42: Heating elect. (kWh) | M42: Cooling elect. (kWh)
B43: Lighting electricity (kWh) | C43: 866.71 | D43: Per building m2 | E43: Per conditioned m2 | G43: January | H43: 79.87 | I43: 587.12 | J43: 2.54 | K43: 16.18 | L43: 176.9 | M43: 0
A44: HVAC | B44: Heating thermal needs (kWh) | C44: ='BAU Results'!C46 -> 1890.76 | G44: February | H44: 73.11 | I44: 534.64 | J44: 1.93 | K44: 12.37 | L44: 130.84 | M44: 0
B45: Heating electricity (kWh) | C45: 560.99 | D45: =C45/$C$1 -> 1.2821456 | E45: =C45/$C$2 -> 2.3617648 | G45: March | H45: 85.5 | I45: 617.92 | J45: 1.05 | K45: 6.82 | L45: 63.13 | M45: 0.08
B46: Heating Setpoint Unmet Degree-Hours [°C·hr] - TOTAL | C46: 49.13 | G46: April | H46: 73.11 | I46: 534.64 | J46: 0.73 | K46: 4.64 | L46: 25.79 | M46: 2.45
G47: May | H47: 83.76 | I47: 613.72 | J47: 0.94 | K47: 5.98 | L47: 2.51 | M47: 7.49
...
